<?xml version="1.0" ?>
<!-- =================================================================================== -->
<!-- |    This document was autogenerated by xacro from arca3.xacro                    | -->
<!-- |    EDITING THIS FILE BY HAND IS NOT RECOMMENDED                                 | -->
<!-- =================================================================================== -->
<robot name="arca3" xmlns:xacro="http://ros.org/wiki/xacro">
  <!-- Inluir archivos de materiales y colores-->
  <material name="blue">
    <color rgba="0 0 0.8 1"/>
  </material>
  <material name="green">
    <color rgba="0.0 0.8 0.0 1.0"/>
  </material>
  <material name="black">
    <color rgba="0.0 0.0 0.0 1.0"/>
  </material>
  <material name="white">
    <color rgba="1.0 1.0 1.0 1.0"/>
  </material>
  <material name="red">
    <color rgba="0.80078125 0.12890625 0.1328125 1.0"/>
  </material>
  <material name="grey">
    <color rgba="0.2 0.2 0.2 1.0"/>
  </material>
  <!-- cwh: caster wheel heat, [m]  -->
  <!-- cw_izz: caster wheel inertia z axis, [kgm^2]  -->
  <!-- yc_dist: distance from the origin to the wheel along the y axis, [m]  -->
  <!-- dwt: driving wheel tread, [m]  -->
  <!-- dw_izz: driving wheel inertia z axis, [kgm^2]  -->
  <!-- xd_dist: distance from the origin to the wheel along the x axis, [m]  -->
  <!-- ch: chassis height, [m]  -->
  <!-- c_izz: chassis inertia z axis, [kgm^2]  -->
  <!-- zch_dist: distance from the ground to the bottom of the chasis, [m]  -->
  <!-- cwlh: caster wheel link height, [m]  -->
  <!-- camera_len: length of the camera (it's a cube), [m] -->
  <!-- =========================================== -->
  <!-- ROBOT DESCRIPTION -->
  <!-- =========================================== -->
  <!-- Chassis -->
  <link name="base_link">
    <visual>
      <origin rpy="0 0 0" xyz="0 0 0.105"/>
      <geometry>
        <mesh filename="package://arca3_description/urdf/meshes/Estructura_arca.stl" scale="0.01 0.01 0.01"/>
      </geometry>
      <material name="white"/>
    </visual>
    <collision>
      <origin rpy="0 0 0" xyz="0 0 0.105"/>
      <geometry>
        <mesh filename="package://arca3_description/urdf/meshes/Estructura_arca.stl" scale="0.01 0.01 0.01"/>
      </geometry>
    </collision>
    <inertial>
      <origin rpy="0 0 0" xyz="0 0 0.105"/>
      <mass value="10.0"/>
      <inertia ixx="0.881333333333" ixy="0.0" ixz="0.0" iyy="0.908333333333" iyz="0.0" izz="0.123"/>
    </inertial>
  </link>
  <gazebo reference="base_link">
    <kp>10000.0</kp>
    <kd>10000.0</kd>
    <mu1>10.0</mu1>
    <mu2>10.0</mu2>
    <material>Gazebo/Grey</material>
  </gazebo>
  <link name="caster_wheel_M1_link">
    <visual>
      <origin rpy="0 0 0" xyz="0 0 0"/>
      <geometry>
        <box size="0.020 0.02 0.035"/>
      </geometry>
      <material name="white"/>
    </visual>
    <collision>
      <origin rpy="0 0 0" xyz="0 0 0"/>
      <geometry>
        <box size="0.020 0.020 0.035"/>
      </geometry>
    </collision>
    <inertial>
      <origin rpy="0 0 0" xyz="0 0 0"/>
      <mass value="0.05"/>
      <inertia ixx="0" ixy="0.0" ixz="0.0" iyy="0" iyz="0.0" izz="0"/>
    </inertial>
  </link>
  <gazebo reference="caster_wheel_M1_link">
    <kp>10000.0</kp>
    <kd>10000.0</kd>
    <mu1>10.0</mu1>
    <mu2>10.0</mu2>
    <material>Gazebo/Grey</material>
  </gazebo>
  <link name="wheel_M1_link">
    <visual>
      <origin rpy="0 0 0" xyz="0 0 0"/>
      <geometry>
        <cylinder length="0.027" radius="0.025"/>
      </geometry>
      <material name="grey"/>
    </visual>
    <collision>
      <origin rpy="0 0 0" xyz="0 0 0"/>
      <geometry>
        <cylinder length="0.027" radius="0.025"/>
      </geometry>
    </collision>
    <inertial>
      <origin rpy="0 0 0" xyz="0 0 0"/>
      <mass value="0.5"/>
      <inertia ixx="0.0001085" ixy="0.0" ixz="0.0" iyy="0.0001085" iyz="0.0" izz="0.00015625"/>
    </inertial>
  </link>
  <gazebo reference="wheel_M1_link">
    <kp>10000.0</kp>
    <kd>10000.0</kd>
    <mu1>10.0</mu1>
    <mu2>10.0</mu2>
    <material>Gazebo/Grey</material>
  </gazebo>
  <joint name="caster_wheel_M1_wheel_M1_joint" type="continuous">
    <parent link="caster_wheel_M1_link"/>
    <child link="wheel_M1_link"/>
    <origin rpy="1.570796 0 0" xyz="0.015 0 -0.035"/>
    <limit effort="1.0" velocity="0.005"/>
    <axis xyz="0 0 1"/>
  </joint>
  <link name="caster_wheel_M2_link">
    <visual>
      <origin rpy="0 0 0" xyz="0 0 0"/>
      <geometry>
        <box size="0.020 0.02 0.035"/>
      </geometry>
      <material name="white"/>
    </visual>
    <collision>
      <origin rpy="0 0 0" xyz="0 0 0"/>
      <geometry>
        <box size="0.020 0.020 0.035"/>
      </geometry>
    </collision>
    <inertial>
      <origin rpy="0 0 0" xyz="0 0 0"/>
      <mass value="0.05"/>
      <inertia ixx="0" ixy="0.0" ixz="0.0" iyy="0" iyz="0.0" izz="0"/>
    </inertial>
  </link>
  <gazebo reference="caster_wheel_M2_link">
    <kp>10000.0</kp>
    <kd>10000.0</kd>
    <mu1>10.0</mu1>
    <mu2>10.0</mu2>
    <material>Gazebo/Grey</material>
  </gazebo>
  <link name="wheel_M2_link">
    <visual>
      <origin rpy="0 0 0" xyz="0 0 0"/>
      <geometry>
        <cylinder length="0.027" radius="0.025"/>
      </geometry>
      <material name="grey"/>
    </visual>
    <collision>
      <origin rpy="0 0 0" xyz="0 0 0"/>
      <geometry>
        <cylinder length="0.027" radius="0.025"/>
      </geometry>
    </collision>
    <inertial>
      <origin rpy="0 0 0" xyz="0 0 0"/>
      <mass value="0.5"/>
      <inertia ixx="0.0001085" ixy="0.0" ixz="0.0" iyy="0.0001085" iyz="0.0" izz="0.00015625"/>
    </inertial>
  </link>
  <gazebo reference="wheel_M2_link">
    <kp>10000.0</kp>
    <kd>10000.0</kd>
    <mu1>10.0</mu1>
    <mu2>10.0</mu2>
    <material>Gazebo/Grey</material>
  </gazebo>
  <joint name="caster_wheel_M2_wheel_M2_joint" type="continuous">
    <parent link="caster_wheel_M2_link"/>
    <child link="wheel_M2_link"/>
    <origin rpy="1.570796 0 0" xyz="0.015 0 -0.035"/>
    <limit effort="1.0" velocity="0.005"/>
    <axis xyz="0 0 1"/>
  </joint>
  <!-- Joint among chassis and caster wheels -->
  <joint name="base_link_caster_wheel_M1_joint" type="continuous">
    <parent link="base_link"/>
    <child link="caster_wheel_M1_link"/>
    <origin rpy="0 0 0" xyz="0.11 0 0.0625"/>
    <limit effort="1.0" velocity="1"/>
    <axis xyz="0 0 1"/>
  </joint>
  <joint name="base_link_caster_wheel_M2_joint" type="continuous">
    <parent link="base_link"/>
    <child link="caster_wheel_M2_link"/>
    <origin rpy="0 0 0" xyz="-0.11 0 0.0625"/>
    <limit effort="1.0" velocity="1"/>
    <axis xyz="0 0 1"/>
  </joint>
  <link name="driving_wheel_M1_link">
    <visual>
      <origin rpy="0 0 0" xyz="0 0 0"/>
      <geometry>
        <cylinder length="0.044" radius="0.0625"/>
      </geometry>
      <material name="blue"/>
    </visual>
    <collision>
      <origin rpy="0 0 0" xyz="0 0 0"/>
      <geometry>
        <cylinder length="0.044" radius="0.0625"/>
      </geometry>
    </collision>
    <inertial>
      <origin rpy="0 0 0" xyz="0 0 0"/>
      <mass value="0.6"/>
      <inertia ixx="0.0006827375" ixy="0.0" ixz="0.0" iyy="0.0006827375" iyz="0.0" izz="0.001171875"/>
    </inertial>
  </link>
  <gazebo reference="driving_wheel_M1_link">
    <kp>10000.0</kp>
    <kd>10000.0</kd>
    <mu1>10.0</mu1>
    <mu2>10.0</mu2>
    <material>Gazebo/Blue</material>
  </gazebo>
  <link name="driving_wheel_M2_link">
    <visual>
      <origin rpy="0 0 0" xyz="0 0 0"/>
      <geometry>
        <cylinder length="0.044" radius="0.0625"/>
      </geometry>
      <material name="blue"/>
    </visual>
    <collision>
      <origin rpy="0 0 0" xyz="0 0 0"/>
      <geometry>
        <cylinder length="0.044" radius="0.0625"/>
      </geometry>
    </collision>
    <inertial>
      <origin rpy="0 0 0" xyz="0 0 0"/>
      <mass value="0.6"/>
      <inertia ixx="0.0006827375" ixy="0.0" ixz="0.0" iyy="0.0006827375" iyz="0.0" izz="0.001171875"/>
    </inertial>
  </link>
  <gazebo reference="driving_wheel_M2_link">
    <kp>10000.0</kp>
    <kd>10000.0</kd>
    <mu1>10.0</mu1>
    <mu2>10.0</mu2>
    <material>Gazebo/Blue</material>
  </gazebo>
  <!-- Joint among chassis and driving wheels -->
  <joint name="joint_base_link_driving_wheel_M1" type="continuous">
    <parent link="base_link"/>
    <child link="driving_wheel_M1_link"/>
    <origin rpy="1.57 0 0" xyz="0 -0.149 0.0625"/>
    <limit effort="15.0" velocity="0.1"/>
    <axis xyz="0 0 -1"/>
  </joint>
  <joint name="joint_base_link_driving_wheel_M2" type="continuous">
    <parent link="base_link"/>
    <child link="driving_wheel_M2_link"/>
    <origin rpy="1.57 0 0" xyz="0 0.149 0.0625"/>
    <limit effort="15.0" velocity="0.1"/>
    <axis xyz="0 0 -1"/>
  </joint>
  <!-- ============================================ -->
  <!-- PLugin - Gazebo drive controller (diff robot)-->
  <!-- ============================================ -->
  <gazebo>
    <plugin filename="libgazebo_ros_diff_drive.so" name="differential_drive_controller">
      <alwaysOn>true</alwaysOn>
      <updateRate>50</updateRate>
      <leftJoint>joint_base_link_driving_wheel_M2</leftJoint>
      <rightJoint>joint_base_link_driving_wheel_M1</rightJoint>
      <wheelSeparation>0.284</wheelSeparation>
      <wheelDiameter>0.125</wheelDiameter>
      <wheelAcceleration>0.2</wheelAcceleration>
      <wheelTorque>30</wheelTorque>
      <commandTopic>cmd_vel</commandTopic>
      <odometryTopic>odom</odometryTopic>
      <odometryFrame>odom</odometryFrame>
      <robotBaseFrame>base_footprint</robotBaseFrame>
      <publishWheelTF>true</publishWheelTF>
      <publishOdom>true</publishOdom>
      <robotBaseFrame>base_link</robotBaseFrame>
      <publishWheelJointState>true</publishWheelJointState>
      <legacyMode>false</legacyMode>
      <rosDebugLevel>false</rosDebugLevel>
      <publishOdomTF>true</publishOdomTF>
      <odometrySource>1</odometrySource>
      <publishTf>1</publishTf>
    </plugin>
  </gazebo>
  <!-- ============================================ -->
  <!--                   SENSORS                    -->
  <!-- ============================================ -->
  <!-- Sensor Laser in the base -->
  <link name="front_laserscanner_link">
    <visual>
      <origin rpy="0.0 0 0" xyz="0 0 0"/>
      <geometry>
        <box size="0.003 0.003 0.003"/>
      </geometry>
      <material name="green"/>
    </visual>
    <collision>
      <origin rpy="0.0 0 0" xyz="0 0 0"/>
      <geometry>
        <box size="0.003 0.003 0.003"/>
      </geometry>
    </collision>
    <inertial>
      <mass value="1e-5"/>
      <origin rpy="0 0 0" xyz="0 0 0"/>
      <inertia ixx="1e-6" ixy="0" ixz="0" iyy="1e-6" iyz="0" izz="1e-6"/>
    </inertial>
  </link>
  <joint name="base_front_laserscanner_joint" type="fixed">
    <axis xyz="0 1 0"/>
    <parent link="base_link"/>
    <child link="front_laserscanner_link"/>
    <origin rpy="0 0 -1.5708" xyz="0.2 0 0.125"/>
  </joint>
  <gazebo reference="front_laserscanner_link">
    <!-- Gazebo sensor -->
    <sensor name="front_rplidar_sensor" type="ray">
      <pose>0 0 0 0 0 0</pose>
      <visualize>true</visualize>
      <!-- put True if you want to visualize the range of the laser -->
      <update_rate>40</update_rate>
      <ray>
        <scan>
          <horizontal>
            <samples>720</samples>
            <resolution>1</resolution>
            <min_angle>0</min_angle>
            <max_angle>3.1416</max_angle>
          </horizontal>
        </scan>
        <range>
          <min>0.10</min>
          <max>2.5</max>
          <resolution>0.01</resolution>
        </range>
        <noise>
          <type>gaussian</type>
          <!-- Noise parameters based on published spec for Hokuyo laser
                         achieving "+-30mm" accuracy at range < 10m.  A mean of 0.0m and
                         stddev of 0.01m will put 99.7% of samples within 0.03m of the true
                         reading. -->
          <mean>0.0</mean>
          <stddev>0.01</stddev>
        </noise>
      </ray>
      <!-- Gazebo plugin -->
      <plugin filename="libgazebo_ros_laser.so" name="gazebo_ros_head_hokuyo_controller">
        <topicName>front_scan</topicName>
        <frameName>front_laserscanner_link</frameName>
      </plugin>
    </sensor>
    <material> Gazebo/Black</material>
  </gazebo>
  <!-- Depth sensor at the middle -->
  <link name="front_dcamera_link">
    <visual>
      <origin rpy="0.0 0 0" xyz="0 0 0"/>
      <geometry>
        <box size="0.002 0.002 0.002"/>
      </geometry>
      <material name="blue"/>
    </visual>
  </link>
  <joint name="base_front_dcamera_joint" type="fixed">
    <parent link="base_link"/>
    <child link="front_dcamera_link"/>
    <origin rpy="0 0 0" xyz="0.15 0 0.5"/>
  </joint>
  <gazebo reference="front_dcamera_link">
    <!-- Gazebo sensor-->
    <sensor name="front_depth_camera" type="depth">
      <update_rate>20</update_rate>
      <camera>
        <horizontal_fov>1.047198</horizontal_fov>
        <image>
          <width>640</width>
          <height>480</height>
          <format>R8G8B8</format>
        </image>
        <clip>
          <near>0.05</near>
          <far>3</far>
        </clip>
      </camera>
      <!-- Gazebo plugin-->
      <plugin filename="libgazebo_ros_openni_kinect.so" name="front_depth_link_controller">
        <baseline>0.2</baseline>
        <alwaysOn>true</alwaysOn>
        <updateRate>1.0</updateRate>
        <cameraName>front_dcamera</cameraName>
        <imageTopicName>front_dcamera/color/image_raw</imageTopicName>
        <cameraInfoTopicName>/front_dcamera/color/camera_info</cameraInfoTopicName>
        <depthImageTopicName>/front_dcamera/depth/image_raw</depthImageTopicName>
        <depthImageInfoTopicName>/front_dcamera/depth/camera_info</depthImageInfoTopicName>
        <pointCloudTopicName>/front_dcamera/depth/points</pointCloudTopicName>
        <frameName>front_dcamera_link</frameName>
        <pointCloudCutoff>0.5</pointCloudCutoff>
        <pointCloudCutoffMax>3.0</pointCloudCutoffMax>
        <distortionK1>0.00000001</distortionK1>
        <distortionK2>0.00000001</distortionK2>
        <distortionK3>0.00000001</distortionK3>
        <distortionT1>0.00000001</distortionT1>
        <distortionT2>0.00000001</distortionT2>
        <CxPrime>0</CxPrime>
        <Cx>0</Cx>
        <Cy>0</Cy>
        <focalLength>0</focalLength>
        <hackBaseline>0</hackBaseline>
      </plugin>
    </sensor>
    <material>Gazebo/Green</material>
  </gazebo>
  <!-- Camera in the head -->
  <link name="camera_link">
    <visual>
      <origin rpy="0 0 0" xyz="0 0 0"/>
      <geometry>
        <box size="0.005 0.005 0.005"/>
      </geometry>
      <material name="red"/>
    </visual>
    <collision>
      <origin rpy="0 0 0" xyz="0 0 0"/>
      <geometry>
        <box size="0.005 0.005 0.005"/>
      </geometry>
    </collision>
    <inertial>
      <mass value="1e-5"/>
      <origin rpy="0 0 0" xyz="0 0 0"/>
      <inertia ixx="1e-6" ixy="0" ixz="0" iyy="1e-6" iyz="0" izz="1e-6"/>
    </inertial>
  </link>
  <joint name="camera_joint" type="fixed">
    <axis xyz="0 1 0"/>
    <origin rpy="0 0 0" xyz="0.1 0 0.666666666667"/>
    <parent link="base_link"/>
    <child link="camera_link"/>
  </joint>
  <!-- camera -->
  <gazebo reference="camera_link">
    <!-- Gazebo sensor-->
    <sensor name="head_camera" type="camera">
      <update_rate>30.0</update_rate>
      <camera name="head">
        <horizontal_fov>1.3962634</horizontal_fov>
        <image>
          <width>800</width>
          <height>800</height>
          <format>R8G8B8</format>
        </image>
        <clip>
          <near>0.02</near>
          <far>300</far>
        </clip>
        <noise>
          <type>gaussian</type>
          <!-- Noise is sampled independently per pixel on each frame.
                    That pixel's noise value is added to each of its color
                    channels, which at that point lie in the range [0,1]. -->
          <mean>0.0</mean>
          <stddev>0.007</stddev>
        </noise>
      </camera>
      <!-- Gazebo plugin-->
      <plugin filename="libgazebo_ros_camera.so" name="camera_controller">
        <alwaysOn>true</alwaysOn>
        <updateRate>0.0</updateRate>
        <cameraName>head_camera</cameraName>
        <imageTopicName>head_camera/image_raw</imageTopicName>
        <cameraInfoTopicName>head_camera/camera_info</cameraInfoTopicName>
        <frameName>camera_link</frameName>
        <hackBaseline>0.07</hackBaseline>
        <distortionK1>0.0</distortionK1>
        <distortionK2>0.0</distortionK2>
        <distortionK3>0.0</distortionK3>
        <distortionT1>0.0</distortionT1>
        <distortionT2>0.0</distortionT2>
      </plugin>
    </sensor>
    <material>Gazebo/Red</material>
  </gazebo>
</robot>

