<?xml version="1.0"?>
<robot name="arca3" xmlns:xacro="http://ros.org/wiki/xacro">

    <!-- Inluir archivos de materiales y colores-->
    <material name="blue">
        <color rgba="0 0 0.8 1"/>
    </material>

    <material name="green">
        <color rgba="0.0 0.8 0.0 1.0"/>
    </material>

    <material name="black">
        <color rgba="0.0 0.0 0.0 1.0"/>
    </material>
    
    <material name="white">
        <color rgba="1.0 1.0 1.0 1.0"/>
    </material>

    <material name="red">
        <color rgba="0.80078125 0.12890625 0.1328125 1.0"/>
    </material>

    <material name="grey">
        <color rgba="0.2 0.2 0.2 1.0"/>
    </material>

    <!-- =========================================== -->
    <!--                 PROPERTIES                  -->
    <!-- =========================================== -->
    <!-- Caster wheels property -->
    <xacro:property name="cwm" value="0.5" />                                   <!-- cwm: caster wheel mass, [kg] -->
    <xacro:property name="cwd" value="0.05" />                                  <!-- cwd: caster wheel diameter, [m]  -->
    <xacro:property name="cwr" value="${cwd/2}" />                              <!-- cwr: caster wheel radius, [m]  -->
    <xacro:property name="cwo" value="0.015" />                                 <!-- cwo: caster wheel offset, [m]  -->
    <xacro:property name="cwt" value="0.027" />                                 <!-- cwt: caster wheel tread, [m]  -->
    <xacro:property name="cwh" value="0.06" />                                  <!-- cwh: caster wheel heat, [m]  -->    

    <xacro:property name="cw_ixx" value="${(cwm/12.0)*(3*cwr*cwr+cwt*cwt)}" />  <!-- cw_ixx: caster wheel inertia x axis, [kgm^2]  -->
    <xacro:property name="cw_iyy" value="${cw_ixx}" />                          <!-- cw_iyy: caster wheel inertia y axis, [kgm^2]  -->
    <xacro:property name="cw_izz" value="${(cwm*cwr*cwr)/2.0}" />               <!-- cw_izz: caster wheel inertia z axis, [kgm^2]  -->    

    <xacro:property name="yc_dist" value="0.149" />                             <!-- yc_dist: distance from the origin to the wheel along the y axis, [m]  -->

    <!-- Driving wheels property -->
    <xacro:property name="dwm" value="0.6" />                                   <!-- dwm: driving wheel mass, [kg] -->
    <xacro:property name="dwd" value="0.125" />                                 <!-- dwd: driving wheel diameter, [m]  -->
    <xacro:property name="dwr" value="${dwd/2}" />                              <!-- dwr: driving wheel radius, [m]  -->
    <xacro:property name="dwt" value="0.044" />                                 <!-- dwt: driving wheel tread, [m]  -->    

    <xacro:property name="dw_ixx" value="${(dwm/12.0)*(3*dwr*dwr+dwt*dwt)}" />  <!-- dw_ixx: driving wheel inertia x axis, [kgm^2]  -->
    <xacro:property name="dw_iyy" value="${dw_ixx}" />                          <!-- dw_iyy: driving wheel inertia y axis, [kgm^2]  -->
    <xacro:property name="dw_izz" value="${(dwm*dwr*dwr)/2.0}" />               <!-- dw_izz: driving wheel inertia z axis, [kgm^2]  -->   

    <xacro:property name="xd_dist" value="0.11" />                              <!-- xd_dist: distance from the origin to the wheel along the x axis, [m]  -->

    <!-- chassis property -->
    <xacro:property name="cm" value="10.0" />                                   <!-- cm: chassis mass, [kg] -->
    <xacro:property name="clod" value="0.300" />                                <!-- clod: chassis longitudinal dimension, [m]  -->
    <xacro:property name="clad" value="0.240" />                                <!-- clad: chassis lateral dimension, [m]  -->
    <xacro:property name="ch" value="1" />                                      <!-- ch: chassis height, [m]  -->

    <xacro:property name="c_ixx" value="${(cm/12.0)*(clad*clad+ch*ch)}" />      <!-- c_ixx: chassis inertia x axis, [kgm^2]  -->
    <xacro:property name="c_iyy" value="${(cm/12.0)*(clod*clod+ch*ch)}" />      <!-- c_iyy: chassis inertia y axis, [kgm^2]  -->
    <xacro:property name="c_izz" value="${(cm/12.0)*(clod*clod+clad*clad)}" />  <!-- c_izz: chassis inertia z axis, [kgm^2]  -->   
    
    <xacro:property name="zch_dist" value="0.105" />                            <!-- zch_dist: distance from the ground to the bottom of the chasis, [m]  -->

    <!-- caster_wheel_link property -->
    <xacro:property name="cwlm" value="0.050" />                                <!-- cwlm: caster wheel link mass, [kg] -->
    <xacro:property name="cwlh" value="${(cwh-cwr)}" />                         <!-- cwlh: caster wheel link height, [m]  -->

    <!-- Sensors -->
    <xacro:property name="laser_len" value="0.003" />                           <!-- laser_len: length of the laser (it's a cube), [m]-->
    <xacro:property name="dcam_len" value="0.002" />                            <!-- dcam_len: length of the depth camera (it's a cube), [m]-->   
    <xacro:property name="camera_len" value="0.005" />                          <!-- camera_len: length of the camera (it's a cube), [m] -->

    <!-- Arms-->
    <!-- Left Arm-->
    <!-- Properties Link1-->
    <xacro:property name="yd_l1" value="0.02" />
    <xacro:property name="la_l1_len" value="0.09" />
    <xacro:property name="la_l1_rad" value="0.03" />
    <xacro:property name="la_l1_mass" value="0.5" />
    <xacro:property name="la_l1_ixx" value="${(la_l1_mass/12.0)*(3*la_l1_rad*la_l1_rad+la_l1_len*la_l1_len)}" />
    <xacro:property name="la_l1_iyy" value="${la_l1_ixx}" />
    <xacro:property name="la_l1_izz" value="${(la_l1_mass*la_l1_rad*la_l1_rad)/2.0}" />

    <!-- Properties Joint1-->
    <xacro:property name="y_la_j1" value="0.14"/>
    <xacro:property name="z_la_j1" value="0.56"/>
    <xacro:property name="ll_la_j1" value="-3.229"/>
    <xacro:property name="lu_la_j1" value="0.349"/>
    <xacro:property name="lv_la_j1" value="0.6"/>

    <!-- Properties Link2-->
    <xacro:property name="zd_l2" value="-0.042" />
    <xacro:property name="la_l2_len" value="0.11" />
    <xacro:property name="la_l2_rad" value="0.02" />
    <xacro:property name="la_l2_mass" value="${la_l1_mass}" />
    <xacro:property name="la_l2_ixx" value="${(la_l2_mass/12.0)*(3*la_l2_rad*la_l2_rad+la_l2_len*la_l2_len)}" />
    <xacro:property name="la_l2_iyy" value="${la_l2_ixx}" />
    <xacro:property name="la_l2_izz" value="${(la_l2_mass*la_l2_rad*la_l2_rad)/2.0}" />

    <!-- Properties Joint2-->
    <xacro:property name="y_la_j2" value="0.062"/>
    <xacro:property name="ll_la_j2" value="-0.175"/>
    <xacro:property name="lu_la_j2" value="1.745"/>
    <xacro:property name="lv_la_j2" value="0.6"/>

    <!-- Properties Link3-->
    <xacro:property name="zd_l3" value="-0.028" />
    <xacro:property name="la_l3_len" value="0.085" />
    <xacro:property name="la_l3_rad" value="0.02" />
    <xacro:property name="la_l3_mass" value="${la_l1_mass}" />
    <xacro:property name="la_l3_ixx" value="${(la_l3_mass/12.0)*(3*la_l3_rad*la_l3_rad+la_l3_len*la_l3_len)}" />
    <xacro:property name="la_l3_iyy" value="${la_l3_ixx}" />
    <xacro:property name="la_l3_izz" value="${(la_l3_mass*la_l3_rad*la_l3_rad)/2.0}" />

    <!-- Properties Joint3-->
    <xacro:property name="z_la_j3" value="-0.097"/>
    <xacro:property name="ll_la_j3" value="-2.094"/>
    <xacro:property name="lu_la_j3" value="0.0"/>
    <xacro:property name="lv_la_j3" value="0.6"/>

    <!-- Properties Link4-->
    <xacro:property name="zd_l4" value="-0.017" />
    <xacro:property name="la_l4_len" value="0.045" />
    <xacro:property name="la_l4_rad" value="0.02" />
    <xacro:property name="la_l4_mass" value="${la_l1_mass}" />
    <xacro:property name="la_l4_ixx" value="${(la_l4_mass/12.0)*(3*la_l4_rad*la_l4_rad+la_l4_len*la_l4_len)}" />
    <xacro:property name="la_l4_iyy" value="${la_l4_ixx}" />
    <xacro:property name="la_l4_izz" value="${(la_l4_mass*la_l4_rad*la_l4_rad)/2.0}" />

    <!-- Properties Joint4-->
    <xacro:property name="z_la_j4" value="-0.064"/>
    <xacro:property name="ll_la_j4" value="-3.1416"/>
    <xacro:property name="lu_la_j4" value="1.5708"/>
    <xacro:property name="lv_la_j4" value="0.6"/>

    <!-- Properties Link5-->
    <xacro:property name="zd_l5" value="-0.002" />
    <xacro:property name="la_l5_sx" value="0.006" />
    <xacro:property name="la_l5_sy" value="0.023" />
    <xacro:property name="la_l5_sz" value="0.04" />
    <xacro:property name="la_l5_mass" value="0.1" />
    <xacro:property name="la_l5_ixx" value="${(la_l5_mass/12.0)*(la_l5_sy*la_l5_sy+la_l5_sz*la_l5_sz)}" />
    <xacro:property name="la_l5_iyy" value="${(la_l5_mass/12.0)*(la_l5_sx*la_l5_sx+la_l5_sz*la_l5_sz)}" />
    <xacro:property name="la_l5_izz" value="${(la_l5_mass/12.0)*(la_l5_sx*la_l5_sx+la_l5_sy*la_l5_sy)}" />

    <!-- Properties Joint5-->
    <xacro:property name="z_la_j5" value="-0.035"/>
    <xacro:property name="ll_la_j5" value="-0.7854"/>
    <xacro:property name="lu_la_j5" value="0.0"/>
    <xacro:property name="lv_la_j5" value="0.6"/>

    <!-- =========================================== -->
    <!--                    MACROS                   -->
    <!-- =========================================== -->
    <!-- caster_wheel_link macro -->
    <xacro:macro name="caster_wheel_link" params="number colour">

        <link name="caster_wheel_M${number}_link">   

            <visual>
                <origin xyz="0 0 0" rpy="0 0 0"/>
                <geometry>
                    <box size="0.020 0.02 ${cwlh}"/>
                </geometry>
                <material name="white"/>
            </visual>

            <collision>
                <origin xyz="0 0 0" rpy="0 0 0"/>
                <geometry>
                    <box size="0.020 0.020 ${cwlh}"/>
                </geometry>
            </collision>

            <inertial>
                <origin xyz="0 0 0" rpy="0 0 0"/>            
                <mass value="${cwlm}" />
                <inertia ixx="0" ixy="0.0" ixz="0.0" iyy="0" iyz="0.0" izz="0"/>
            </inertial>
 
        </link>

        <gazebo reference="caster_wheel_M${number}_link">
            <kp>10000.0</kp>
            <kd>10000.0</kd>
            <mu1>10.0</mu1>
            <mu2>10.0</mu2>
            <material>Gazebo/Grey</material>
        </gazebo>

        <link name="wheel_M${number}_link">    

            <visual>
                <origin xyz="0 0 0" rpy="0 0 0"/>
                <geometry>
                    <cylinder length="${cwt}" radius="${cwr}"/>
                </geometry>
                <material name="grey"/>
            </visual>    

            <collision>
                <origin xyz="0 0 0" rpy="0 0 0"/>
                <geometry>
                    <cylinder length="${cwt}" radius="${cwr}"/>
                </geometry>
            </collision>

            <inertial>
                <origin xyz="0 0 0" rpy="0 0 0"/>            
                <mass value="${cwm}" />
                <inertia ixx="${cw_ixx}" ixy="0.0" ixz="0.0" iyy="${cw_iyy}" iyz="0.0" izz="${cw_izz}"/>
            </inertial>

        </link>

        <gazebo reference="wheel_M${number}_link">
            <kp>10000.0</kp>
            <kd>10000.0</kd>
            <mu1>10.0</mu1>
            <mu2>10.0</mu2>
            <material>Gazebo/${colour}</material>
        </gazebo>

        <joint name="caster_wheel_M${number}_wheel_M${number}_joint" type="continuous">
            <parent link="caster_wheel_M${number}_link"/>
            <child link="wheel_M${number}_link"/>
            <origin xyz="${cwo} 0 ${-cwlh}" rpy="1.570796 0 0"/>
            <limit  effort="1.0" velocity="0.005"/>
            <axis xyz="0 0 1"/>
        </joint>

    </xacro:macro>

    <!-- driving_wheel_link macro -->
    <xacro:macro name="driving_wheel_link" params="number colour">
        
        <link name="driving_wheel_M${number}_link">    
            
            <visual>
                <origin xyz="0 0 0" rpy="0 0 0"/>
                <geometry>
                    <cylinder length="${dwt}" radius="${dwr}"/>
                </geometry>
                <material name="blue"/>
            </visual>  

            <collision>
                <origin xyz="0 0 0" rpy="0 0 0"/>
                <geometry>
                    <cylinder length="${dwt}" radius="${dwr}"/>
                </geometry>
            </collision>  

            <inertial>
                <origin xyz="0 0 0" rpy="0 0 0"/>            
                <mass value="${dwm}" />
                <inertia ixx="${dw_ixx}" ixy="0.0" ixz="0.0" iyy="${dw_iyy}" iyz="0.0" izz="${dw_izz}"/>
            </inertial>
        

        </link>

        <gazebo reference="driving_wheel_M${number}_link">
            <kp>10000.0</kp>
            <kd>10000.0</kd>
            <mu1>10.0</mu1>
            <mu2>10.0</mu2>
            <material>Gazebo/${colour}</material>
        </gazebo>

    </xacro:macro>

    <!-- arm link macro -->
    <xacro:macro name="m_link_cylinder" params="name origin_xyz origin_rpy length radius mass ixx ixy ixz iyy iyz izz vis_material">
        <link name="${name}">
        <inertial>
            <mass value="${mass}" />
            <origin rpy="${origin_rpy}" xyz="${origin_xyz}" />
            <inertia ixx="${ixx}" ixy="${ixy}" ixz="${ixz}" iyy="${iyy}" iyz="${iyz}" izz="${izz}" />
        </inertial>
        <collision>
            <origin rpy="${origin_rpy}" xyz="${origin_xyz}" />
            <geometry>
            <cylinder length="${length}" radius="${radius}"/>
            </geometry>
        </collision>
        <visual>
            <origin rpy="${origin_rpy}" xyz="${origin_xyz}" />
            <geometry>
            <cylinder length="${length}" radius="${radius}"/>
            </geometry>
            <material name="${vis_material}"/>
        </visual>
        </link>
    </xacro:macro>

    <!-- joint base-arm macro -->
    <xacro:macro name="m_joint" params="name type axis_xyz origin_rpy origin_xyz parent child limit_e limit_l limit_u limit_v">
        <joint name="${name}" type="${type}">
            <axis xyz="${axis_xyz}" />
            <limit effort="${limit_e}" lower="${limit_l}" upper="${limit_u}" velocity="${limit_v}" />
            <origin rpy="${origin_rpy}" xyz="${origin_xyz}" />
            <parent link="${parent}" />
            <child link="${child}" />
        </joint>
        <transmission name="trans_${name}">
            <type>transmission_interface/SimpleTransmission</type>
            <joint name="${name}">
                <hardwareInterface>hardware_interface/EffortJointInterface</hardwareInterface>
            </joint>
            <actuator name="motor_${name}">
                <hardwareInterface>hardware_interface/EffortJointInterface</hardwareInterface>
                <mechanicalReduction>1</mechanicalReduction>
            </actuator>
        </transmission>
    </xacro:macro>

    <!-- gripper box macro -->
    <xacro:macro name="m_link_box" params="name origin_xyz origin_rpy size mass ixx ixy ixz iyy iyz izz vis_material">
        <link name="${name}">
            <inertial>
                <mass value="${mass}" />
                <origin rpy="${origin_rpy}" xyz="${origin_xyz}" />
                <inertia ixx="${ixx}" ixy="${ixy}" ixz="${ixz}" iyy="${iyy}" iyz="${iyz}" izz="${izz}" />
            </inertial>
            <collision>
                <origin rpy="${origin_rpy}" xyz="${origin_xyz}" />
                <geometry>
                    <box size="${size}" />
                </geometry>
            </collision>
            <visual>
                <origin rpy="${origin_rpy}" xyz="${origin_xyz}" />
                <geometry>
                    <box size="${size}" />
                </geometry>
                <material name="${vis_material}"/>
            </visual>
        </link>
    </xacro:macro>

    <!-- driving wheel transmission -->
    <!-- <xacro:macro name="driving_wheel_transmission" params="number">
        <transmission name="tran${number}">
            <type>transmission_interface/SimpleTransmission</type>
            <joint name="joint_base_link_driving_wheel_M${number}">
                <hardwareInterface>hardware_interface/VelocityJointInterface</hardwareInterface>
            </joint>
            <actuator name="motor${number}">
                <hardwareInterface>hardware_interface/VelocityJointInterface</hardwareInterface>
                <mechanicalReduction>1</mechanicalReduction>
            </actuator>
        </transmission>
    </xacro:macro> -->

    <!-- =========================================== -->
    <!--              ROBOT DESCRIPTION              -->
    <!-- =========================================== -->
    <!-- Chassis -->
    <link name="base_link">
        <visual>
            <origin xyz="0 0 ${zch_dist}" rpy="0 0 0"/>     
            <geometry>
                <mesh filename="package://arca3_description/urdf/meshes/Estructura_arca.stl" scale="0.01 0.01 0.01"/>
            </geometry>
            <material name="white"/>
        </visual>

        <collision>
            <origin xyz="0 0 ${zch_dist}" rpy="0 0 0"/>
            <geometry>
                <mesh filename="package://arca3_description/urdf/meshes/Estructura_arca.stl" scale="0.01 0.01 0.01"/>
            </geometry>
        </collision>

        <inertial>
            <origin xyz="0 0 ${zch_dist}" rpy="0 0 0"/>            
            <mass value="${cm}"/>
            <inertia ixx="${c_ixx}" ixy="0.0" ixz="0.0" iyy="${c_iyy}" iyz="0.0" izz="${c_izz}"/>
        </inertial>      
    </link>

    <gazebo reference="base_link">
        <kp>10000.0</kp>
        <kd>10000.0</kd>
        <mu1>10.0</mu1>
        <mu2>10.0</mu2>
        <material>Gazebo/Grey</material>
    </gazebo>

    <!-- Caster wheels and link -->    
    <xacro:caster_wheel_link number="1" colour="Grey"/>
    <xacro:caster_wheel_link number="2" colour="Grey"/>
    
    <!-- Joint among chassis and caster wheels -->
    <joint name="base_link_caster_wheel_M1_joint" type="continuous">
    	<parent link="base_link"/>
    	<child link="caster_wheel_M1_link"/>
        <origin xyz="${xd_dist} 0 ${dwr}" rpy="0 0 0"/>
        <limit effort="1.0" velocity="1"/>
        <axis xyz="0 0 1"/>
	</joint>

    <joint name="base_link_caster_wheel_M2_joint" type="continuous">
    	<parent link="base_link"/>
    	<child link="caster_wheel_M2_link"/>
        <origin xyz="-${xd_dist} 0 ${dwr}" rpy="0 0 0"/>
        <limit effort="1.0" velocity="1"/>
        <axis xyz="0 0 1"/>
	</joint>

    <!-- Driving wheels -->
    <xacro:driving_wheel_link number="1" colour="Blue"/>
    <xacro:driving_wheel_link number="2" colour="Blue"/>

    <!-- Joint among chassis and driving wheels -->
    <joint name="joint_base_link_driving_wheel_M1" type="continuous">
    	<parent link="base_link"/>
    	<child link="driving_wheel_M1_link"/>
        <origin xyz="0 -${yc_dist} ${dwr}" rpy="1.57 0 0"/>
        <limit effort="15.0" velocity="0.1"/>
        <axis xyz="0 0 -1"/>
	</joint>

    <joint name="joint_base_link_driving_wheel_M2" type="continuous">
    	<parent link="base_link"/>
    	<child link="driving_wheel_M2_link"/>
        <origin xyz="0 ${yc_dist} ${dwr}" rpy="1.57 0 0"/>
        <limit effort="15.0" velocity="0.1"/>
        <axis xyz="0 0 -1"/>
	</joint>

    <!-- ============================================ -->
    <!--                 LEFT ARM                     -->
    <!-- ============================================ -->

    <!-- Link1: Left arm arca -->
    <m_link_cylinder name="la_link1"
                     origin_xyz="0 ${yd_l1} 0" origin_rpy="1.5708 0 0"
                     length="${la_l1_len}" radius="${la_l1_rad}"
                     mass="${la_l1_mass}"
                     ixx="${la_l1_ixx}" ixy="0" ixz="0"
                     iyy="${la_l1_iyy}" iyz="0"
                     izz="${la_l1_izz}"
                     vis_material="white"/>

    <!-- Joint1: base_link - Link1 -->           
    <m_joint name="joint_base_to_lalink1" type="revolute"
             axis_xyz="0 1 0"
             origin_rpy="0 0 0" origin_xyz="0 ${y_la_j1} ${z_la_j1}"
             parent="base_link" child="la_link1"
             limit_e="10000" limit_l="${ll_la_j1}" limit_u="${lu_la_j1}" limit_v="${lv_la_j1}" />
    
    <!-- Link2: Brazo arca -->
    <m_link_cylinder name="la_link2"
                     origin_xyz="0 0.0 ${zd_l2}" origin_rpy="0 0 0"
                     length="${la_l2_len}" radius="${la_l2_rad}"
                     mass="${la_l2_mass}"
                     ixx="${la_l2_ixx}" ixy="0" ixz="0"
                     iyy="${la_l2_iyy}" iyz="0"
                     izz="${la_l2_izz}"
                     vis_material="white"/>
    
    <!-- Joint2: Link1 - Link2 -->           
    <m_joint name="joint_lalink1_to_lalink2" type="revolute"
             axis_xyz="1 0 0"
             origin_rpy="0 0 0" origin_xyz="0 ${y_la_j2} 0"
             parent="la_link1" child="la_link2"
             limit_e="10000" limit_l="${ll_la_j2}" limit_u="${lu_la_j2}" limit_v="${lv_la_j2}" />
    
    <!-- Link3: Brazo arca -->
    <m_link_cylinder name="la_link3"
                     origin_xyz="0 0.0 ${zd_l3}" origin_rpy="0 0 0"
                     length="${la_l3_len}" radius="${la_l3_rad}"
                     mass="${la_l3_mass}"
                     ixx="${la_l3_ixx}" ixy="0" ixz="0"
                     iyy="${la_l3_iyy}" iyz="0"
                     izz="${la_l3_izz}"
                     vis_material="white"/>
    
    <!-- Joint3: Link2 - Link3 -->        
    <m_joint name="joint_lalink2_to_lalink3" type="revolute"
             axis_xyz="0 1 0"
             origin_rpy="0 0 0" origin_xyz="0 0 ${z_la_j3}"
             parent="la_link2" child="la_link3"
             limit_e="10000" limit_l="${ll_la_j3}" limit_u="${lu_la_j3}" limit_v="${lv_la_j3}" />
    
    <!-- Link4: Brazo arca -->
    <m_link_cylinder name="la_link4"
                     origin_xyz="0 0.0 ${zd_l4}" origin_rpy="0 0 0"
                     length="${la_l4_len}"  radius="${la_l4_rad}" 
                     mass="${la_l4_mass}" 
                     ixx="${la_l4_ixx}" ixy="0" ixz="0"
                     iyy="${la_l4_iyy}" iyz="0"
                     izz="${la_l4_izz}"
                     vis_material="white"/>
    
    <!-- Joint4: Link3 - Link4 -->           
    <m_joint name="joint_lalink3_to_lalink4" type="revolute"
             axis_xyz="0 0 1"
             origin_rpy="0 0 0" origin_xyz="0 0.0 ${z_la_j4}"
             parent="la_link3" child="la_link4"
             limit_e="10000" limit_l="${ll_la_j4}" limit_u="${lu_la_j4}" limit_v="${lv_la_j4}" />
    
    <!-- Link5: manito -->
    <m_link_box name="la_link5"
                origin_xyz="0 0.0 ${zd_l5}" origin_rpy="0 0 1.5708"
                size="${la_l5_sx} ${la_l5_sy} ${la_l5_sz}"
                mass="${la_l5_mass}"
                ixx="${la_l5_ixx}" ixy="0" ixz="0"
                iyy="${la_l5_iyy}" iyz="0"
                izz="${la_l5_izz}"
                vis_material="grey"/>
    
    <!-- Joint4: Link4 - Link5 -->           
    <m_joint name="joint_lalink4_to_lalink5" type="revolute"
             axis_xyz="1 0 0"
             origin_rpy="0 0 0" origin_xyz="0 0.0 ${z_la_j5}"
             parent="la_link4" child="la_link5"
             limit_e="10000" limit_l="${ll_la_j5}" limit_u="${lu_la_j5}" limit_v="${lv_la_j5}" />

    <!-- ============================================ -->
    <!--                 RIGHT ARM                 -->
    <!-- ============================================ -->
    <!-- Link1: right arm arca -->
    <m_link_cylinder name="ra_link1"
                     origin_xyz="0 ${-1*yd_l1} 0" origin_rpy="1.5708 0 0"
                     length="${la_l1_len}" radius="${la_l1_rad}"
                     mass="${la_l1_mass}"
                     ixx="${la_l1_ixx}" ixy="0" ixz="0"
                     iyy="${la_l1_iyy}" iyz="0"
                     izz="${la_l1_izz}"
                     vis_material="white"/>
    
    <!-- Joint1: base_link - Link1 -->         
    <m_joint name="joint_base_to_ralink1" type="revolute"
             axis_xyz="0 1 0"
             origin_rpy="0 0 0" origin_xyz="0 ${-1*y_la_j1} ${z_la_j1}"
             parent="base_link" child="ra_link1"
             limit_e="10000" limit_l="${ll_la_j1}" limit_u="${lu_la_j1}" limit_v="${lv_la_j1}" />
    
    <!-- Link2: Brazo arca -->
    <m_link_cylinder name="ra_link2"
                     origin_xyz="0 0.0 ${zd_l2}" origin_rpy="0 0 0"
                     length="${la_l2_len}" radius="${la_l2_rad}"
                     mass="${la_l2_mass}"
                     ixx="${la_l2_ixx}" ixy="0" ixz="0"
                     iyy="${la_l2_iyy}" iyz="0"
                     izz="${la_l2_izz}"
                     vis_material="white"/>
    
    <!-- Joint2: Link1 - Link2 -->           
    <m_joint name="joint_ralink1_to_ralink2" type="revolute"
             axis_xyz="1 0 0"
             origin_rpy="0 0 0" origin_xyz="0 ${-1*y_la_j2} 0"
             parent="ra_link1" child="ra_link2"
             limit_e="10000" limit_l="${-1*lu_la_j2}" limit_u="${-1*ll_la_j2}" limit_v="${lv_la_j2}" />
    
    <!-- Link3: Brazo arca -->
    <m_link_cylinder name="ra_link3"
                     origin_xyz="0 0.0 ${zd_l3}" origin_rpy="0 0 0"
                     length="${la_l3_len}" radius="${la_l3_rad}"
                     mass="${la_l3_mass}"
                     ixx="${la_l3_ixx}" ixy="0" ixz="0"
                     iyy="${la_l3_iyy}" iyz="0"
                     izz="${la_l3_izz}"
                     vis_material="white"/>
    
    <!-- Joint3: Link2 - Link3 -->       
    <m_joint name="joint_ralink2_to_ralink3" type="revolute"
             axis_xyz="0 1 0"
             origin_rpy="0 0 0" origin_xyz="0 0 ${z_la_j3}"
             parent="ra_link2" child="ra_link3"
             limit_e="10000" limit_l="${ll_la_j3}" limit_u="${lu_la_j3}" limit_v="0.6" />
    
    <!-- Link4: Brazo arca -->
    <m_link_cylinder name="ra_link4"
                     origin_xyz="0 0.0 ${zd_l4}" origin_rpy="0 0 0"
                     length="${la_l4_len}" radius="${la_l4_rad}"
                     mass="${la_l4_mass}"
                     ixx="${la_l4_ixx}" ixy="0" ixz="0"
                     iyy="${la_l4_iyy}" iyz="0"
                     izz="${la_l4_izz}"
                     vis_material="white"/>
    
    <!-- Joint4: Link3 - Link4 -->          
    <m_joint name="joint_ralink3_to_ralink4" type="revolute"
             axis_xyz="0 0 1"
             origin_rpy="0 0 0" origin_xyz="0 0.0 ${z_la_j4}"
             parent="ra_link3" child="ra_link4"
             limit_e="10000" limit_l="${-1*lu_la_j4}" limit_u="${-1*ll_la_j4}" limit_v="${lv_la_j4}" />

    <!-- Link5: manito -->
    <m_link_box name="ra_link5"
                origin_xyz="0 0.0 ${zd_l5}" origin_rpy="0 0 1.5708"
                size="${la_l5_sx} ${la_l5_sy} ${la_l5_sz}" mass="${la_l5_mass}"
                ixx="${la_l5_ixx}" ixy="0" ixz="0"
                iyy="${la_l5_iyy}" iyz="0"
                izz="${la_l5_izz}"
                vis_material="grey"/>
    
    <!-- Joint4: Link4 - Link5 -->           
    <m_joint name="joint_ralink4_to_ralink5" type="revolute"
             axis_xyz="1 0 0"
             origin_rpy="0 0 0" origin_xyz="0 0.0 ${z_la_j5}"
             parent="ra_link4" child="ra_link5"
             limit_e="10000" limit_l="${lu_la_j5}" limit_u="${-1*ll_la_j5}" limit_v="${lv_la_j5}" />    
    
    
    <!-- ============================================ -->
    <!--                 Transmission                 -->
    <!-- ============================================ -->
    <!-- <xacro:driving_wheel_transmission number="1"/>
    <xacro:driving_wheel_transmission number="2"/> -->
    
    <!-- ============================================ -->
    <!-- PLugin - Gazebo drive controller (diff robot)-->
    <!-- ============================================ -->
    <gazebo>
        <plugin name="differential_drive_controller" filename="libgazebo_ros_diff_drive.so">
            <alwaysOn>true</alwaysOn>
            <updateRate>50</updateRate>
            <leftJoint>joint_base_link_driving_wheel_M2</leftJoint>
            <rightJoint>joint_base_link_driving_wheel_M1</rightJoint>
            <wheelSeparation>${clad+dwt}</wheelSeparation>
            <wheelDiameter>${dwd}</wheelDiameter>
            <wheelAcceleration>0.2</wheelAcceleration>
            <wheelTorque>30</wheelTorque>
            <commandTopic>cmd_vel</commandTopic>
            <odometryTopic>odom</odometryTopic>
            <odometryFrame>odom</odometryFrame>
            <robotBaseFrame>base_footprint</robotBaseFrame>
            <publishWheelTF>true</publishWheelTF>
            <publishOdom>true</publishOdom>
            <robotBaseFrame>base_link</robotBaseFrame>
            <publishWheelJointState>true</publishWheelJointState>
            <legacyMode>false</legacyMode>
            <rosDebugLevel>false</rosDebugLevel>
            <publishOdomTF>true</publishOdomTF>
            <odometrySource>1</odometrySource>
            <publishTf>1</publishTf>
        </plugin>
    </gazebo>

    <!-- ros_control plugin -->
    <gazebo>
        <plugin name="gazebo_ros_control" filename="libgazebo_ros_control.so">
            <robotNamespace>/arca3</robotNamespace>
            <robotSimType>gazebo_ros_control/DefaultRobotHWSim</robotSimType>
            <legacyModeNS>true</legacyModeNS>
        </plugin>
    </gazebo>	
    <!-- ============================================ -->
    <!--                   SENSORS                    -->
    <!-- ============================================ -->
    
    <!-- Sensor Laser in the base -->
    <link name="front_laserscanner_link">      
        <visual>
            <origin rpy="0.0 0 0" xyz="0 0 0"/>
            <geometry>
                <box size="${laser_len} ${laser_len} ${laser_len}"/>
            </geometry>
            <material name="green"/>
        </visual>

        <collision>
            <origin rpy="0.0 0 0" xyz="0 0 0"/>
            <geometry>
                <box size="${laser_len} ${laser_len} ${laser_len}"/>
            </geometry>
        </collision>

        <inertial>
            <mass value="1e-5" />
            <origin xyz="0 0 0" rpy="0 0 0"/>
            <inertia ixx="1e-6" ixy="0" ixz="0" iyy="1e-6" iyz="0" izz="1e-6" />
        </inertial>

    </link>

    <joint name="base_front_laserscanner_joint" type="fixed">
        <axis xyz="0 1 0" />
        <parent link="base_link"/>
        <child link="front_laserscanner_link"/>
        <origin xyz="${2*clod/3} 0 ${ch/8}" rpy="0 0 -1.5708"/>
    </joint>

    <gazebo reference="front_laserscanner_link">
        <!-- Gazebo sensor -->
        <sensor type="ray" name="front_rplidar_sensor">
            <pose>0 0 0 0 0 0</pose>
            <visualize>false</visualize> <!-- put True if you want to visualize the range of the laser -->
            <update_rate>40</update_rate>
            <ray>
                <scan>
                    <horizontal>
                        <samples>720</samples>
                        <resolution>1</resolution>
                        <min_angle>0</min_angle>
                        <max_angle>3.1416</max_angle>
                    </horizontal>
                </scan>
                <range>
                    <min>0.10</min>
                    <max>2.5</max>
                    <resolution>0.01</resolution>
                </range>
                <noise>
                    <type>gaussian</type>
                    <!-- Noise parameters based on published spec for Hokuyo laser
                         achieving "+-30mm" accuracy at range < 10m.  A mean of 0.0m and
                         stddev of 0.01m will put 99.7% of samples within 0.03m of the true
                         reading. -->
                    <mean>0.0</mean>
                    <stddev>0.01</stddev>
                </noise>
            </ray>
            <!-- Gazebo plugin -->
            <plugin name="gazebo_ros_head_hokuyo_controller" filename="libgazebo_ros_laser.so">
                <topicName>front_scan</topicName>
                <frameName>front_laserscanner_link</frameName>
            </plugin>
        </sensor>
        <material> Gazebo/Black</material>
    </gazebo>

    <!-- Depth sensor at the middle -->
    <link name="front_dcamera_link">
      <visual>
        <origin rpy="0.0 0 0" xyz="0 0 0"/>
        <geometry>
          <box size="${dcam_len} ${dcam_len} ${dcam_len}"/>
        </geometry>
        <material name="blue"/>
      </visual>
    </link>

    <joint name="base_front_dcamera_joint" type="fixed">
      <parent link="base_link"/>
      <child link="front_dcamera_link"/>
      <origin xyz="${clod/2} 0 ${ch/2}" rpy="0 0 0"/>
    </joint>

    <gazebo reference="front_dcamera_link">
        <!-- Gazebo sensor-->
        <sensor name="front_depth_camera" type="depth">
            <update_rate>20</update_rate>
            <camera>
                <horizontal_fov>1.047198</horizontal_fov>
                <image>
                <width>640</width>
                <height>480</height>
                <format>R8G8B8</format>
                </image>
                <clip>
                <near>0.05</near>
                <far>3</far>
                </clip>
            </camera>
            <!-- Gazebo plugin-->
            <plugin name="front_depth_link_controller" filename="libgazebo_ros_openni_kinect.so">
                <baseline>0.2</baseline>
                <alwaysOn>true</alwaysOn>
                <updateRate>1.0</updateRate>
                <cameraName>front_dcamera</cameraName>
                <imageTopicName>front_dcamera/color/image_raw</imageTopicName>
                <cameraInfoTopicName>/front_dcamera/color/camera_info</cameraInfoTopicName>
                <depthImageTopicName>/front_dcamera/depth/image_raw</depthImageTopicName>
                <depthImageInfoTopicName>/front_dcamera/depth/camera_info</depthImageInfoTopicName>
                <pointCloudTopicName>/front_dcamera/depth/points</pointCloudTopicName>
                <frameName>front_dcamera_link</frameName>
                <pointCloudCutoff>0.5</pointCloudCutoff>
                <pointCloudCutoffMax>3.0</pointCloudCutoffMax>
                <distortionK1>0.00000001</distortionK1>
                <distortionK2>0.00000001</distortionK2>
                <distortionK3>0.00000001</distortionK3>
                <distortionT1>0.00000001</distortionT1>
                <distortionT2>0.00000001</distortionT2>
                <CxPrime>0</CxPrime>
                <Cx>0</Cx>
                <Cy>0</Cy>
                <focalLength>0</focalLength>
                <hackBaseline>0</hackBaseline>
            </plugin>
        </sensor>
        <material>Gazebo/Green</material>
    </gazebo>

    <!-- Camera in the head -->
    <link name="camera_link">
        <visual>
            <origin xyz="0 0 0" rpy="0 0 0"/>
            <geometry>
                <box size="${camera_len} ${camera_len} ${camera_len}"/>
            </geometry>
            <material name="red"/>
        </visual>

        <collision>
            <origin xyz="0 0 0" rpy="0 0 0"/>
            <geometry>
                <box size="${camera_len} ${camera_len} ${camera_len}"/>
            </geometry>
        </collision>

        <inertial>
            <mass value="1e-5" />
            <origin xyz="0 0 0" rpy="0 0 0"/>
            <inertia ixx="1e-6" ixy="0" ixz="0" iyy="1e-6" iyz="0" izz="1e-6" />
        </inertial>
    </link>

    <joint name="camera_joint" type="fixed">
        <axis xyz="0 1 0" />
        <origin xyz="${clod/3} 0 ${2*ch/3}" rpy="0 0 0"/>
        <parent link="base_link"/>
        <child link="camera_link"/>
    </joint>

    <gazebo reference="camera_link">
        <!-- Gazebo sensor-->
        <sensor type="camera" name="head_camera">
            <update_rate>30.0</update_rate>
            <camera name="head">
            <horizontal_fov>1.3962634</horizontal_fov>
            <image>
                <width>800</width>
                <height>800</height>
                <format>R8G8B8</format>
            </image>
            <clip>
                <near>0.02</near>
                <far>300</far>
            </clip>
            <noise>
                <type>gaussian</type>
                <!-- Noise is sampled independently per pixel on each frame.
                    That pixel's noise value is added to each of its color
                    channels, which at that point lie in the range [0,1]. -->
                <mean>0.0</mean>
                <stddev>0.007</stddev>
            </noise>
            </camera>
            <!-- Gazebo plugin-->
            <plugin name="camera_controller" filename="libgazebo_ros_camera.so">
            <alwaysOn>true</alwaysOn>
            <updateRate>0.0</updateRate>
            <cameraName>head_camera</cameraName>
            <imageTopicName>head_camera/image_raw</imageTopicName>
            <cameraInfoTopicName>head_camera/camera_info</cameraInfoTopicName>
            <frameName>camera_link</frameName>
            <hackBaseline>0.07</hackBaseline>
            <distortionK1>0.0</distortionK1>
            <distortionK2>0.0</distortionK2>
            <distortionK3>0.0</distortionK3>
            <distortionT1>0.0</distortionT1>
            <distortionT2>0.0</distortionT2>
            </plugin>
        </sensor>
        <material>Gazebo/Red</material>
    </gazebo>

</robot>